Workbook

Sheet Company definition
A1: Personnel | B1: Num | C1: Gross annual salary | D1: annual employment cost | E1: total | H1: Nº | I1: Concept | J1: val | K1: Amount
A2: General manager | B2: 1 | C2: 76243 | D2: 91781.35 | E2: =B2*D2 -> 91781.35 | H2: 1 | I2: Total direct costs | K2: =D24 -> 246372.66
A3: Project manager | B3: 1 | C3: 40550 | D3: 53039.4 | E3: =B3*D3 -> 53039.4 | H3: 2 | I3: Total indirect cotsts | K3: =B75 -> 335500.22
A4: Service coordinator | B4: 1 | C4: 25135 | D4: 32876.58 | E4: =B4*D4 -> 32876.58 | H4: 3 | I4: Sum of direct and indirect costs | K4: =K2+K3 -> 581872.88
A5: Systems analyst | B5: 1 | C5: 35574 | D5: 46530.79 | E5: =B5*D5 -> 46530.79 | H5: 4 | I5: Desired profit | J5: 0.25 | K5: =K4*J5 -> 145468.22
A6: Technology consultant | B6: 1 | C6: 41988 | D6: 54920.3 | E6: =B6*D6 -> 54920.3 | H6: 5 | I6: Required billing/revenue | K6: =K4+K5 -> 727341.1
A7: Software architect | B7: 1 | C7: 44369 | D7: 58034.65 | E7: =B7*D7 -> 58034.65 | H7: 6 | I7: Possible billing based on productive hours and calculated hourly rates | K7: =E90 -> 781150.64
A8: Senior developer | B8: 2 | C8: 39879 | D8: 52161.73 | E8: =B8*D8 -> 104323.46 | H8: 7 | I8: Margin between total cost and billing | K8: =IFERROR((K7-K6)/K6,"sin valor") -> 0.073981155
A9: Junior developer | B9: 4 | C9: 25872 | D9: 33840.58 | E9: =B9*D9 -> 135362.32
A10: Sales representative | B10: 1 | C10: 26849 | D10: 35118.49 | E10: =B10*D10 -> 35118.49
A11: TOTAL | B11: =SUM(B2:B10) -> 13 | E11: =SUM(E2:E10) -> 611987.34
A14: Personnel | B14: TOTAL | C14: Prod(%) | D14: Direct cost | E14: IC (%) | F14: Indirect cost
A15: General manager | B15: =D2 -> 91781.35 | C15: 0 | D15: =ROUND(B15*C15,2) -> 0 | E15: =1-C15 -> 1 | F15: =ROUND(B15*E15,2) -> 91781.35
A16: Project manager | B16: =D3 -> 53039.4 | C16: 0.65 | D16: =ROUND(B16*C16,2) -> 34475.61 | E16: =1-C16 -> 0.35 | F16: =ROUND(B16*E16,2) -> 18563.79
A17: Service coordinator | B17: =D4 -> 32876.58 | C17: 0.5 | D17: =ROUND(B17*C17,2) -> 16438.29 | E17: =1-C17 -> 0.5 | F17: =ROUND(B17*E17,2) -> 16438.29
A18: Systems analyst | B18: =D5 -> 46530.79 | C18: 0.8 | D18: =ROUND(B18*C18,2) -> 37224.63 | E18: =1-C18 -> 0.2 | F18: =ROUND(B18*E18,2) -> 9306.16
A19: Technology consultant | B19: =D6 -> 54920.3 | C19: 0.85 | D19: =ROUND(B19*C19,2) -> 46682.26 | E19: =1-C19 -> 0.15 | F19: =ROUND(B19*E19,2) -> 8238.05
A20: Software architect | B20: =D7 -> 58034.65 | C20: 0.75 | D20: =ROUND(B20*C20,2) -> 43525.99 | E20: =1-C20 -> 0.25 | F20: =ROUND(B20*E20,2) -> 14508.66
A21: Senior developer | B21: =D8 -> 52161.73 | C21: 0.85 | D21: =ROUND(B21*C21,2) -> 44337.47 | E21: =1-C21 -> 0.15 | F21: =ROUND(B21*E21,2) -> 7824.26
A22: Junior developer | B22: =D9 -> 33840.58 | C22: 0.7 | D22: =ROUND(B22*C22,2) -> 23688.41 | E22: =1-C22 -> 0.3 | F22: =ROUND(B22*E22,2) -> 10152.17
A23: Sales representative | B23: =D10 -> 35118.49 | C23: 0 | D23: =ROUND(B23*C23,2) -> 0 | E23: =1-C23 -> 1 | F23: =ROUND(B23*E23,2) -> 35118.49
A24: TOTAL | B24: =SUM(B15:B23) -> 458303.87 | D24: =SUM(D15:D23) -> 246372.66 | F24: =SUM(F15:F23) -> 211931.22
A26: Service | B26: Monthly cost | C26: Annual cost
A27: Cleaning | B27: 850 | C27: =B27*12 -> 10200
A28: Advertising | B28: 800 | C28: =B28*12 -> 9600
A29: Accounting services | B29: 550 | C29: =B29*12 -> 6600
A30: Quality control | B30: 400 | C30: =B30*12 -> 4800
A31: Taxes and fees | B31: 120 | C31: =B31*12 -> 1440
A32: Rent / lease | B32: 1350 | C32: =B32*12 -> 16200
A33: Vehicle leasing fees | B33: 900 | C33: =B33*12 -> 10800
A34: Maintenance, repair and upkeep | B34: 140 | C34: =B34*12 -> 1680
A35: Small tools and equipment | B35: 120 | C35: =B35*12 -> 1440
A36: Electricity consumption | B36: 120 | C36: =B36*12 -> 1440
A37: Heating energy consumption | B37: 180 | C37: =B37*12 -> 2160
A38: Water consumption | B38: 55 | C38: =B38*12 -> 660
... A49: Depreciation expense of fixed assets | B49: 685 | C49: =B49*12 -> 8220
A50: Total | C50: =SUM(C27:C49) -> 107040
A52: Equipment/licenses | B52: Units | C52: Price | D52: Total cost | E52: Annual cost | F52: Type | G52: Term
A53: Azure data center | B53: 1 | C53: 8000 | D53: =C53*B53 -> 8000 | E53: =D53 -> 8000 | F53: Rental
A54: Administrative equipment | B54: 3 | C54: 1000 | D54: =C54*B54 -> 3000 | E54: =D54/G54 -> 750 | F54: Depreciation | G54: 4
...

Sheet Costs_init
A1: Category 1: IrBoard development costs breakdown | L1: with proportional increase | N1: IrBoard costs
A2: I1 | B2: I2 | C2: I3 | D2: Description | E2: Resource | F2: Cuantity | G2: Units | H2: Price | I2: Subtotal | J2: Subtotal (2) | K2: Total | N2: Cat. Num | O2: Category | P2: Total
A3: 01 | D3: Project management | H3: =_xlfn.XLOOKUP(E3,$Q$20:$Q$25,$R$20:$R$25,"") | I3: =IFERROR(H3*F3,"") | K3: =SUM(J4:J19) -> 1493.4638 | L3: =IFERROR(I3+($P$10*F3),"") | N3: 01 | O3: IrBoard development costs breakdown | P3: =K74 -> 13026.517
B4: 001 | D4: Design project schedule | E4: Project manager | F4: 2 | G4: Hours | H4: =_xlfn.XLOOKUP(E4,$Q$20:$Q$25,$R$20:$R$25,"") -> 49.782125 | I4: =IFERROR(H4*F4,"") -> 99.564251 | J4: =I4 -> 99.564251 | L4: =IFERROR(I4+($P$10*F4),"") -> 122.72425 | N4: 02 | O4: Other | P4: =K81 -> 172.5
B5: 002 | D5: Generate budget | E5: Project manager | F5: 2 | G5: Hours | H5: =_xlfn.XLOOKUP(E5,$Q$20:$Q$25,$R$20:$R$25,"") -> 49.782125 | I5: =IFERROR(H5*F5,"") -> 99.564251 | J5: =I5 -> 99.564251 | L5: =IFERROR(I5+($P$10*F5),"") -> 122.72425 | N5: total | P5: =SUM(P3:P4) -> 13199.017
B6: 003 | D6: Periodic project management | H6: =_xlfn.XLOOKUP(E6,$Q$20:$Q$25,$R$20:$R$25,"") | I6: =IFERROR(H6*F6,"") | J6: =SUM(I7:I19) -> 1294.3353
C7: 01 | D7: Periodic project management 1 | E7: Project manager | F7: 2 | G7: Hours | H7: =_xlfn.XLOOKUP(E7,$Q$20:$Q$25,$R$20:$R$25,"") -> 49.782125 | I7: =IFERROR(H7*F7,"") -> 99.564251 | L7: =IFERROR(I7+($P$10*F7),"") -> 122.72425 | O7: Profit (25%) | P7: =0.25*(P3+P4) -> 3299.7543
C8: 02 | D8: Periodic project management 2 | E8: Project manager | F8: 2 | G8: Hours | H8: =_xlfn.XLOOKUP(E8,$Q$20:$Q$25,$R$20:$R$25,"") -> 49.782125 | I8: =IFERROR(H8*F8,"") -> 99.564251 | L8: =IFERROR(I8+($P$10*F8),"") -> 122.72425 | O8: amount to be increased on the first category | P8: =P5+P7-P3 -> 3472.2543
C9: 03 | D9: Periodic project management 3 | E9: Project manager | F9: 2 | G9: Hours | H9: =_xlfn.XLOOKUP(E9,$Q$20:$Q$25,$R$20:$R$25,"") -> 49.782125 | I9: =IFERROR(H9*F9,"") -> 99.564251 | L9: =IFERROR(I9+($P$10*F9),"") -> 122.72425 | O9: total hours | P9: =SUM(F4:F73) -> 300
C10: 04 | D10: Periodic project management 4 | E10: Project manager | F10: 2 | G10: Hours | H10: =_xlfn.XLOOKUP(E10,$Q$20:$Q$25,$R$20:$R$25,"") -> 49.782125 | I10: =IFERROR(H10*F10,"") -> 99.564251 | L10: =IFERROR(I10+($P$10*F10),"") -> 122.72425 | O10: Dilution increase per billable hour | P10: =ROUNDUP(P8/P9,2) -> 11.58
C11: 05 | D11: Periodic project management 5 | E11: Project manager | F11: 2 | G11: Hours | H11: =_xlfn.XLOOKUP(E11,$Q$20:$Q$25,$R$20:$R$25,"") -> 49.782125 | I11: =IFERROR(H11*F11,"") -> 99.564251 | L11: =IFERROR(I11+($P$10*F11),"") -> 122.72425 | O11: estimated client cost: | P11: =P5+P7 -> 16498.772
C12: 06 | D12: Periodic project management 6 | E12: Project manager | F12: 2 | G12: Hours | H12: =_xlfn.XLOOKUP(E12,$Q$20:$Q$25,$R$20:$R$25,"") -> 49.782125 | I12: =IFERROR(H12*F12,"") -> 99.564251 | L12: =IFERROR(I12+($P$10*F12),"") -> 122.72425
C13: 07 | D13: Periodic project management 7 | E13: Project manager | F13: 2 | G13: Hours | H13: =_xlfn.XLOOKUP(E13,$Q$20:$Q$25,$R$20:$R$25,"") -> 49.782125 | I13: =IFERROR(H13*F13,"") -> 99.564251 | L13: =IFERROR(I13+($P$10*F13),"") -> 122.72425
C14: 08 | D14: Periodic project management 8 | E14: Project manager | F14: 2 | G14: Hours | H14: =_xlfn.XLOOKUP(E14,$Q$20:$Q$25,$R$20:$R$25,"") -> 49.782125 | I14: =IFERROR(H14*F14,"") -> 99.564251 | L14: =IFERROR(I14+($P$10*F14),"") -> 122.72425
C15: 09 | D15: Periodic project management 9 | E15: Project manager | F15: 2 | G15: Hours | H15: =_xlfn.XLOOKUP(E15,$Q$20:$Q$25,$R$20:$R$25,"") -> 49.782125 | I15: =IFERROR(H15*F15,"") -> 99.564251 | L15: =IFERROR(I15+($P$10*F15),"") -> 122.72425
C16: 10 | D16: Periodic project management 10 | E16: Project manager | F16: 2 | G16: Hours | H16: =_xlfn.XLOOKUP(E16,$Q$20:$Q$25,$R$20:$R$25,"") -> 49.782125 | I16: =IFERROR(H16*F16,"") -> 99.564251 | L16: =IFERROR(I16+($P$10*F16),"") -> 122.72425
C17: 11 | D17: Periodic project management 11 | E17: Project manager | F17: 2 | G17: Hours | H17: =_xlfn.XLOOKUP(E17,$Q$20:$Q$25,$R$20:$R$25,"") -> 49.782125 | I17: =IFERROR(H17*F17,"") -> 99.564251 | L17: =IFERROR(I17+($P$10*F17),"") -> 122.72425
C18: 12 | D18: Periodic project management 12 | E18: Project manager | F18: 2 | G18: Hours | H18: =_xlfn.XLOOKUP(E18,$Q$20:$Q$25,$R$20:$R$25,"") -> 49.782125 | I18: =IFERROR(H18*F18,"") -> 99.564251 | L18: =IFERROR(I18+($P$10*F18),"") -> 122.72425
C19: 13 | D19: Periodic project management 13 | E19: Project manager | F19: 2 | G19: Hours | H19: =_xlfn.XLOOKUP(E19,$Q$20:$Q$25,$R$20:$R$25,"") -> 49.782125 | I19: =IFERROR(H19*F19,"") -> 99.564251 | L19: =IFERROR(I19+($P$10*F19),"") -> 122.72425 | Q19: Available resources | R19: Hourly rate (without profit)
A20: 02 | D20: Analysis/Software Requirements | H20: =_xlfn.XLOOKUP(E20,$Q$20:$Q$25,$R$20:$R$25,"") | I20: =IFERROR(H20*F20,"") | K20: =SUM(J21:J30) -> 2307.2124 | L20: =IFERROR(I20+($P$10*F20),"") | Q20: Project manager | R20: ='Company definition'!F82 -> 49.782125
B21: 001 | D21: Determine project scope | E21: System Analyst | F21: 1 | G21: Hours | H21: =_xlfn.XLOOKUP(E21,$Q$20:$Q$25,$R$20:$R$25,"") -> 42.159269 | I21: =IFERROR(H21*F21,"") -> 42.159269 | J21: =I21 -> 42.159269 | L21: =IFERROR(I21+($P$10*F21),"") -> 53.739269 | Q21: Technology consultant | R21: ='Company definition'!F85 -> 45.220459
B22: 002 | D22: Review Regulatory Standards | E22: Technology consultant | F22: 4 | G22: Hours | H22: =_xlfn.XLOOKUP(E22,$Q$20:$Q$25,$R$20:$R$25,"") -> 45.220459 | I22: =IFERROR(H22*F22,"") -> 180.88184 | J22: =I22 -> 180.88184 | L22: =IFERROR(I22+($P$10*F22),"") -> 227.20184 | Q22: System Analyst | R22: ='Company definition'!F84 -> 42.159269
B23: 003 | D23: Identify required Documentation | E23: System Analyst | F23: 2 | G23: Hours | H23: =_xlfn.XLOOKUP(E23,$Q$20:$Q$25,$R$20:$R$25,"") -> 42.159269 | I23: =IFERROR(H23*F23,"") -> 84.318538 | J23: =I23 -> 84.318538 | L23: =IFERROR(I23+($P$10*F23),"") -> 107.47854 | Q23: Software architect | R23: ='Company definition'!F86 -> 49.154057
B24: 004 | D24: Determine hand-ins for the project | E24: System Analyst | F24: 1 | G24: Hours | H24: =_xlfn.XLOOKUP(E24,$Q$20:$Q$25,$R$20:$R$25,"") -> 42.159269 | I24: =IFERROR(H24*F24,"") -> 42.159269 | J24: =I24 -> 42.159269 | L24: =IFERROR(I24+($P$10*F24),"") -> 53.739269 | Q24: Senior software engineer | R24: ='Company definition'!F87 -> 43.846666
B25: 005 | D25: Adapt project template to typst | E25: System Analyst | F25: 2 | G25: Hours | H25: =_xlfn.XLOOKUP(E25,$Q$20:$Q$25,$R$20:$R$25,"") -> 42.159269 | I25: =IFERROR(H25*F25,"") -> 84.318538 | J25: =I25 -> 84.318538 | L25: =IFERROR(I25+($P$10*F25),"") -> 107.47854 | Q25: Junior software engineer | R25: ='Company definition'!F88 -> 38.551814
B26: 006 | D26: Analyze existing systems | E26: Technology consultant | F26: 6 | G26: Hours | H26: =_xlfn.XLOOKUP(E26,$Q$20:$Q$25,$R$20:$R$25,"") -> 45.220459 | I26: =IFERROR(H26*F26,"") -> 271.32276 | J26: =I26 -> 271.32276 | L26: =IFERROR(I26+($P$10*F26),"") -> 340.80276
B27: 007 | D27: Draft preliminary software requirements | E27: System Analyst | F27: 22 | G27: Hours | H27: =_xlfn.XLOOKUP(E27,$Q$20:$Q$25,$R$20:$R$25,"") -> 42.159269 | I27: =IFERROR(H27*F27,"") -> 927.50392 | J27: =I27 -> 927.50392 | L27: =IFERROR(I27+($P$10*F27),"") -> 1182.2639
B28: 008 | D28: Model auxiliary diagrams | E28: System Analyst | F28: 6 | G28: Hours | H28: =_xlfn.XLOOKUP(E28,$Q$20:$Q$25,$R$20:$R$25,"") -> 42.159269 | I28: =IFERROR(H28*F28,"") -> 252.95562 | J28: =I28 -> 252.95562 | L28: =IFERROR(I28+($P$10*F28),"") -> 322.43562
B29: 009 | D29: Review software requirements | E29: System Analyst | F29: 2 | G29: Hours | H29: =_xlfn.XLOOKUP(E29,$Q$20:$Q$25,$R$20:$R$25,"") -> 42.159269 | I29: =IFERROR(H29*F29,"") -> 84.318538 | J29: =I29 -> 84.318538 | L29: =IFERROR(I29+($P$10*F29),"") -> 107.47854
B30: 010 | D30: Modify requirements with feedback | E30: System Analyst | F30: 8 | G30: Hours | H30: =_xlfn.XLOOKUP(E30,$Q$20:$Q$25,$R$20:$R$25,"") -> 42.159269 | I30: =IFERROR(H30*F30,"") -> 337.27415 | J30: =I30 -> 337.27415 | L30: =IFERROR(I30+($P$10*F30),"") -> 429.91415
A31: 03 | D31: Design | H31: =_xlfn.XLOOKUP(E31,$Q$20:$Q$25,$R$20:$R$25,"") | I31: =IFERROR(H31*F31,"") | K31: =SUM(J32:J38) -> 2273.3693 | L31: =IFERROR(I31+($P$10*F31),"")
B32: 001 | D32: Design architecture | E32: Software architect | F32: 10 | G32: Hours | H32: =_xlfn.XLOOKUP(E32,$Q$20:$Q$25,$R$20:$R$25,"") -> 49.154057 | I32: =IFERROR(H32*F32,"") -> 491.54057 | J32: =I32 -> 491.54057 | L32: =IFERROR(I32+($P$10*F32),"") -> 607.34057
B33: 002 | D33: Design brand identity | E33: Junior software engineer | F33: 3 | G33: Hours | H33: =_xlfn.XLOOKUP(E33,$Q$20:$Q$25,$R$20:$R$25,"") -> 38.551814 | I33: =IFERROR(H33*F33,"") -> 115.65544 | J33: =I33 -> 115.65544 | L33: =IFERROR(I33+($P$10*F33),"") -> 150.39544
B34: 003 | D34: Design project management | E34: Senior software engineer | F34: 8 | G34: Hours | H34: =_xlfn.XLOOKUP(E34,$Q$20:$Q$25,$R$20:$R$25,"") -> 43.846666 | I34: =IFERROR(H34*F34,"") -> 350.77333 | J34: =I34 -> 350.77333 | L34: =IFERROR(I34+($P$10*F34),"") -> 443.41333
B35: 004 | D35: Design stakeholder management | E35: Senior software engineer | F35: 4 | G35: Hours | H35: =_xlfn.XLOOKUP(E35,$Q$20:$Q$25,$R$20:$R$25,"") -> 43.846666 | I35: =IFERROR(H35*F35,"") -> 175.38667 | J35: =I35 -> 175.38667 | L35: =IFERROR(I35+($P$10*F35),"") -> 221.70667
B36: 005 | D36: Design requirement management | E36: Senior software engineer | F36: 6 | G36: Hours | H36: =_xlfn.XLOOKUP(E36,$Q$20:$Q$25,$R$20:$R$25,"") -> 43.846666 | I36: =IFERROR(H36*F36,"") -> 263.08 | J36: =I36 -> 263.08 | L36: =IFERROR(I36+($P$10*F36),"") -> 332.56
B37: 006 | D37: Design user management | E37: Senior software engineer | F37: 10 | G37: Hours | H37: =_xlfn.XLOOKUP(E37,$Q$20:$Q$25,$R$20:$R$25,"") -> 43.846666 | I37: =IFERROR(H37*F37,"") -> 438.46666 | J37: =I37 -> 438.46666 | L37: =IFERROR(I37+($P$10*F37),"") -> 554.26666
B38: 007 | D38: Design document management | E38: Senior software engineer | F38: 10 | G38: Hours | H38: =_xlfn.XLOOKUP(E38,$Q$20:$Q$25,$R$20:$R$25,"") -> 43.846666 | I38: =IFERROR(H38*F38,"") -> 438.46666 | J38: =I38 -> 438.46666 | L38: =IFERROR(I38+($P$10*F38),"") -> 554.26666
A39: 04 | D39: Set up SonarQube for Quality Assurance | E39: Senior software engineer | F39: 3 | G39: Hours | H39: =_xlfn.XLOOKUP(E39,$Q$20:$Q$25,$R$20:$R$25,"") -> 43.846666 | I39: =IFERROR(H39*F39,"") -> 131.54 | J39: =SUM(I39) -> 131.54 | K39: =SUM(J39) -> 131.54 | L39: =IFERROR(I39+($P$10*F39),"") -> 166.28
A40: 05 | D40: Development | H40: =_xlfn.XLOOKUP(E40,$Q$20:$Q$25,$R$20:$R$25,"") | I40: =IFERROR(H40*F40,"") | K40: =SUM(J41:J50) -> 4386.8988 | L40: =IFERROR(I40+($P$10*F40),"")
...

Sheet Client_init
A1: Detailed client budget | G1: Simplified client budget
A2: I1 | B2: I2 | C2: Description | D2: Cost | E2: Total | G2: Cat. Num | H2: Category | I2: Total
A3: 01 | C3: Project management | E3: =SUM(D4:D6) -> 1840.8638 | G3: 01 | H3: IrBoard development costs breakdown | I3: =E54 -> 16500.517
B4: 001 | C4: Design project schedule | D4: =Costs_init!L4 -> 122.72425 | G4: total | I4: =SUM(I3) -> 16500.517
B5: 002 | C5: Generate budget | D5: =Costs_init!L5 -> 122.72425
B6: 003 | C6: Periodic project management | D6: =SUM(Costs_init!L7:L19) -> 1595.4153
A7: 02 | C7: Analysis/Software Requirements | E7: =SUM(D8:D17) -> 2932.5324
B8: 001 | C8: Determine project scope | D8: =Costs_init!L21 -> 53.739269
B9: 002 | C9: Review Regulatory Standards | D9: =Costs_init!L22 -> 227.20184
B10: 003 | C10: Identify required Documentation | D10: =Costs_init!L23 -> 107.47854
B11: 004 | C11: Determine hand-ins for the project | D11: =Costs_init!L24 -> 53.739269
B12: 005 | C12: Adapt project template to typst | D12: =Costs_init!L25 -> 107.47854
B13: 006 | C13: Analyze existing systems | D13: =Costs_init!L26 -> 340.80276
B14: 007 | C14: Draft preliminary software requirements | D14: =Costs_init!L27 -> 1182.2639
B15: 008 | C15: Model auxiliary diagrams | D15: =Costs_init!L28 -> 322.43562
B16: 009 | C16: Review software requirements | D16: =Costs_init!L29 -> 107.47854
B17: 010 | C17: Modify requirements with feedback | D17: =Costs_init!L30 -> 429.91415
A18: 03 | C18: Design | D18: =Costs_init!L31 | E18: =SUM(D19:D25) -> 2863.9493
B19: 001 | C19: Design architecture | D19: =Costs_init!L32 -> 607.34057
B20: 002 | C20: Design brand identity | D20: =Costs_init!L33 -> 150.39544
B21: 003 | C21: Design project management | D21: =Costs_init!L34 -> 443.41333
B22: 004 | C22: Design stakeholder management | D22: =Costs_init!L35 -> 221.70667
B23: 005 | C23: Design requirement management | D23: =Costs_init!L36 -> 332.56
B24: 006 | C24: Design user management | D24: =Costs_init!L37 -> 554.26666
B25: 007 | C25: Design document management | D25: =Costs_init!L38 -> 554.26666
A26: 04 | C26: Set up SonarQube for Quality Assurance | D26: =Costs_init!L39 -> 166.28 | E26: =D26 -> 166.28
A27: 05 | C27: Development | D27: =Costs_init!L40 | E27: =SUM(D28:D30) -> 5602.7988
B28: 001 | C28: Set up architecture | D28: =Costs_init!L41 -> 242.93623
B29: 002 | C29: Set up development enviroment | D29: =Costs_init!L42 -> 182.20217
B30: 003 | C30: Develop code | D30: =SUM(Costs_init!L44:L50) -> 5177.6604
A31: 06 | C31: Testing | E31: =SUM(D32:D40) -> 1364.1487
B32: 001 | C32: Test project management module | D32: =Costs_init!L52 -> 200.52726
B33: 002 | C33: Test stakeholder management module | D33: =Costs_init!L53 -> 150.39544
B34: 003 | C34: Test requirement management module | D34: =Costs_init!L54 -> 250.65907
B35: 004 | C35: Test user management module | D35: =Costs_init!L55 -> 150.39544
B36: 005 | C36: Test document management | D36: =Costs_init!L56 -> 150.39544
B37: 006 | C37: Test modifying concurrency system | D37: =Costs_init!L57 -> 100.26363
B38: 007 | C38: Test search and filtering | D38: =Costs_init!L58 -> 150.39544
B39: 008 | C39: Usability and accesibility testing | D39: =Costs_init!L59 -> 100.26363
B40: 009 | C40: Load testing | D40: =Costs_init!L60 -> 110.85333
...

Sheet Costs_final
A1: Category 1: IrBoard development costs breakdown | N1: IrBoard costs
A2: I1 | B2: I2 | C2: I3 | D2: Description | E2: Resource | F2: Cuantity | G2: Units | H2: Price | I2: Subtotal | J2: Subtotal (2) | K2: Total | L2: deviation | N2: Cat. Num | O2: Category | P2: Total | Q2: deviation from original
A3: 01 | D3: Project management | H3: =_xlfn.XLOOKUP(E3,$Q$20:$Q$25,$R$20:$R$25,"") | I3: =IFERROR(H3*F3,"") | K3: =SUM(J4:J19) -> 1194.771 | L3: =((K3-Costs_init!K3)/Costs_init!K3) -> -0.2 | N3: 01 | O3: IrBoard development costs breakdown | P3: =K74 -> 13383.613 | Q3: =((P3-Costs_init!P3)/Costs_init!P3) -> 0.027412946
B4: 001 | D4: Design project schedule | E4: Project manager | F4: 2 | G4: Hours | H4: =_xlfn.XLOOKUP(E4,$Q$20:$Q$25,$R$20:$R$25,"") -> 49.782125 | I4: =IFERROR(H4*F4,"") -> 99.564251 | J4: =I4 -> 99.564251 | L4: =((J4-Costs_init!J4)/Costs_init!J4) -> 0 | N4: 02 | O4: Other | P4: =K81 -> 172.5 | Q4: =((P4-Costs_init!P4)/Costs_init!P4) -> 0
B5: 002 | D5: Generate budget | E5: Project manager | F5: 2 | G5: Hours | H5: =_xlfn.XLOOKUP(E5,$Q$20:$Q$25,$R$20:$R$25,"") -> 49.782125 | I5: =IFERROR(H5*F5,"") -> 99.564251 | J5: =I5 -> 99.564251 | L5: =((J5-Costs_init!J5)/Costs_init!J5) -> 0 | N5: total | P5: =SUM(P3:P4) -> 13556.113 | Q5: =((P5-Costs_init!P5)/Costs_init!P5) -> 0.027054682
B6: 003 | D6: Periodic project management | H6: =_xlfn.XLOOKUP(E6,$Q$20:$Q$25,$R$20:$R$25,"") | I6: =IFERROR(H6*F6,"") | J6: =SUM(I7:I19) -> 995.64251 | L6: =((J6-Costs_init!J6)/Costs_init!J6) -> -0.23076923
C7: 01 | D7: Periodic project management 1 | E7: Project manager | F7: 1 | G7: Hours | H7: =_xlfn.XLOOKUP(E7,$Q$20:$Q$25,$R$20:$R$25,"") -> 49.782125 | I7: =IFERROR(H7*F7,"") -> 49.782125 | L7: =((I7-Costs_init!I7)/Costs_init!I7) -> -0.5 | O7: Actual profit | P7: =Client_init!I4-Costs_final!P5 -> 2944.4048
C8: 02 | D8: Periodic project management 2 | E8: Project manager | F8: 2 | G8: Hours | H8: =_xlfn.XLOOKUP(E8,$Q$20:$Q$25,$R$20:$R$25,"") -> 49.782125 | I8: =IFERROR(H8*F8,"") -> 99.564251 | L8: =((I8-Costs_init!I8)/Costs_init!I8) -> 0 | O8: Profit deviation | P8: =((P7-Costs_init!P7)/Costs_init!P7) -> -0.1076897
C9: 03 | D9: Periodic project management 3 | E9: Project manager | F9: 1 | G9: Hours | H9: =_xlfn.XLOOKUP(E9,$Q$20:$Q$25,$R$20:$R$25,"") -> 49.782125 | I9: =IFERROR(H9*F9,"") -> 49.782125 | L9: =((I9-Costs_init!I9)/Costs_init!I9) -> -0.5 | P9: =(0.21)*(P3+P4) -> 2846.7836
C10: 04 | D10: Periodic project management 4 | E10: Project manager | F10: 2 | G10: Hours | H10: =_xlfn.XLOOKUP(E10,$Q$20:$Q$25,$R$20:$R$25,"") -> 49.782125 | I10: =IFERROR(H10*F10,"") -> 99.564251 | L10: =((I10-Costs_init!I10)/Costs_init!I10) -> 0 | P10: =P5+P9 -> 16402.896
C11: 05 | D11: Periodic project management 5 | E11: Project manager | F11: 1 | G11: Hours | H11: =_xlfn.XLOOKUP(E11,$Q$20:$Q$25,$R$20:$R$25,"") -> 49.782125 | I11: =IFERROR(H11*F11,"") -> 49.782125 | L11: =((I11-Costs_init!I11)/Costs_init!I11) -> -0.5
C12: 06 | D12: Periodic project management 6 | E12: Project manager | F12: 1 | G12: Hours | H12: =_xlfn.XLOOKUP(E12,$Q$20:$Q$25,$R$20:$R$25,"") -> 49.782125 | I12: =IFERROR(H12*F12,"") -> 49.782125 | L12: =((I12-Costs_init!I12)/Costs_init!I12) -> -0.5
C13: 07 | D13: Periodic project management 7 | E13: Project manager | F13: 2 | G13: Hours | H13: =_xlfn.XLOOKUP(E13,$Q$20:$Q$25,$R$20:$R$25,"") -> 49.782125 | I13: =IFERROR(H13*F13,"") -> 99.564251 | L13: =((I13-Costs_init!I13)/Costs_init!I13) -> 0
C14: 08 | D14: Periodic project management 8 | E14: Project manager | F14: 2 | G14: Hours | H14: =_xlfn.XLOOKUP(E14,$Q$20:$Q$25,$R$20:$R$25,"") -> 49.782125 | I14: =IFERROR(H14*F14,"") -> 99.564251 | L14: =((I14-Costs_init!I14)/Costs_init!I14) -> 0
C15: 09 | D15: Periodic project management 9 | E15: Project manager | F15: 2 | G15: Hours | H15: =_xlfn.XLOOKUP(E15,$Q$20:$Q$25,$R$20:$R$25,"") -> 49.782125 | I15: =IFERROR(H15*F15,"") -> 99.564251 | L15: =((I15-Costs_init!I15)/Costs_init!I15) -> 0
C16: 10 | D16: Periodic project management 10 | E16: Project manager | F16: 2 | G16: Hours | H16: =_xlfn.XLOOKUP(E16,$Q$20:$Q$25,$R$20:$R$25,"") -> 49.782125 | I16: =IFERROR(H16*F16,"") -> 99.564251 | L16: =((I16-Costs_init!I16)/Costs_init!I16) -> 0
C17: 11 | D17: Periodic project management 11 | E17: Project manager | F17: 1 | G17: Hours | H17: =_xlfn.XLOOKUP(E17,$Q$20:$Q$25,$R$20:$R$25,"") -> 49.782125 | I17: =IFERROR(H17*F17,"") -> 49.782125 | L17: =((I17-Costs_init!I17)/Costs_init!I17) -> -0.5
C18: 12 | D18: Periodic project management 12 | E18: Project manager | F18: 1 | G18: Hours | H18: =_xlfn.XLOOKUP(E18,$Q$20:$Q$25,$R$20:$R$25,"") -> 49.782125 | I18: =IFERROR(H18*F18,"") -> 49.782125 | L18: =((I18-Costs_init!I18)/Costs_init!I18) -> -0.5
C19: 13 | D19: Periodic project management 13 | E19: Project manager | F19: 2 | G19: Hours | H19: =_xlfn.XLOOKUP(E19,$Q$20:$Q$25,$R$20:$R$25,"") -> 49.782125 | I19: =IFERROR(H19*F19,"") -> 99.564251 | L19: =((I19-Costs_init!I19)/Costs_init!I19) -> 0 | Q19: Available resources | R19: Hourly rate (without profit)
A20: 02 | D20: Analysis/Software Requirements | H20: =_xlfn.XLOOKUP(E20,$Q$20:$Q$25,$R$20:$R$25,"") | I20: =IFERROR(H20*F20,"") | K20: =SUM(J21:J30) -> 2433.6902 | L20: =((K20-Costs_init!K20)/Costs_init!K20) -> 0.054818449 | Q20: Project manager | R20: ='Company definition'!F82 -> 49.782125
B21: 001 | D21: Determine project scope | E21: System Analyst | F21: 1 | G21: Hours | H21: =_xlfn.XLOOKUP(E21,$Q$20:$Q$25,$R$20:$R$25,"") -> 42.159269 | I21: =IFERROR(H21*F21,"") -> 42.159269 | J21: =I21 -> 42.159269 | L21: =((J21-Costs_init!J21)/Costs_init!J21) -> 0 | Q21: Technology consultant | R21: ='Company definition'!F85 -> 45.220459
B22: 002 | D22: Review Regulatory Standards | E22: Technology consultant | F22: 4 | G22: Hours | H22: =_xlfn.XLOOKUP(E22,$Q$20:$Q$25,$R$20:$R$25,"") -> 45.220459 | I22: =IFERROR(H22*F22,"") -> 180.88184 | J22: =I22 -> 180.88184 | L22: =((J22-Costs_init!J22)/Costs_init!J22) -> 0 | Q22: System Analyst | R22: ='Company definition'!F84 -> 42.159269
B23: 003 | D23: Identify required Documentation | E23: System Analyst | F23: 1 | G23: Hours | H23: =_xlfn.XLOOKUP(E23,$Q$20:$Q$25,$R$20:$R$25,"") -> 42.159269 | I23: =IFERROR(H23*F23,"") -> 42.159269 | J23: =I23 -> 42.159269 | L23: =((J23-Costs_init!J23)/Costs_init!J23) -> -0.5 | Q23: Software architect | R23: ='Company definition'!F86 -> 49.154057
B24: 004 | D24: Determine hand-ins for the project | E24: System Analyst | F24: 1 | G24: Hours | H24: =_xlfn.XLOOKUP(E24,$Q$20:$Q$25,$R$20:$R$25,"") -> 42.159269 | I24: =IFERROR(H24*F24,"") -> 42.159269 | J24: =I24 -> 42.159269 | L24: =((J24-Costs_init!J24)/Costs_init!J24) -> 0 | Q24: Senior software engineer | R24: ='Company definition'!F87 -> 43.846666
B25: 005 | D25: Adapt project template to typst | E25: System Analyst | F25: 2 | G25: Hours | H25: =_xlfn.XLOOKUP(E25,$Q$20:$Q$25,$R$20:$R$25,"") -> 42.159269 | I25: =IFERROR(H25*F25,"") -> 84.318538 | J25: =I25 -> 84.318538 | L25: =((J25-Costs_init!J25)/Costs_init!J25) -> 0 | Q25: Junior software engineer | R25: ='Company definition'!F88 -> 38.551814
B26: 006 | D26: Analyze existing systems | E26: Technology consultant | F26: 6 | G26: Hours | H26: =_xlfn.XLOOKUP(E26,$Q$20:$Q$25,$R$20:$R$25,"") -> 45.220459 | I26: =IFERROR(H26*F26,"") -> 271.32276 | J26: =I26 -> 271.32276 | L26: =((J26-Costs_init!J26)/Costs_init!J26) -> 0
B27: 007 | D27: Draft preliminary software requirements | E27: System Analyst | F27: 22 | G27: Hours | H27: =_xlfn.XLOOKUP(E27,$Q$20:$Q$25,$R$20:$R$25,"") -> 42.159269 | I27: =IFERROR(H27*F27,"") -> 927.50392 | J27: =I27 -> 927.50392 | L27: =((J27-Costs_init!J27)/Costs_init!J27) -> 0
B28: 008 | D28: Model auxiliary diagrams | E28: System Analyst | F28: 8 | G28: Hours | H28: =_xlfn.XLOOKUP(E28,$Q$20:$Q$25,$R$20:$R$25,"") -> 42.159269 | I28: =IFERROR(H28*F28,"") -> 337.27415 | J28: =I28 -> 337.27415 | L28: =((J28-Costs_init!J28)/Costs_init!J28) -> 0.33333333
B29: 009 | D29: Review software requirements | E29: System Analyst | F29: 4 | G29: Hours | H29: =_xlfn.XLOOKUP(E29,$Q$20:$Q$25,$R$20:$R$25,"") -> 42.159269 | I29: =IFERROR(H29*F29,"") -> 168.63708 | J29: =I29 -> 168.63708 | L29: =((J29-Costs_init!J29)/Costs_init!J29) -> 1
B30: 010 | D30: Modify requirements with feedback | E30: System Analyst | F30: 8 | G30: Hours | H30: =_xlfn.XLOOKUP(E30,$Q$20:$Q$25,$R$20:$R$25,"") -> 42.159269 | I30: =IFERROR(H30*F30,"") -> 337.27415 | J30: =I30 -> 337.27415 | L30: =((J30-Costs_init!J30)/Costs_init!J30) -> 0
A31: 03 | D31: Design | H31: =_xlfn.XLOOKUP(E31,$Q$20:$Q$25,$R$20:$R$25,"") | I31: =IFERROR(H31*F31,"") | K31: =SUM(J32:J38) -> 2361.0627 | L31: =((K31-Costs_init!K31)/Costs_init!K31) -> 0.038574169
B32: 001 | D32: Design architecture | E32: Software architect | F32: 10 | G32: Hours | H32: =_xlfn.XLOOKUP(E32,$Q$20:$Q$25,$R$20:$R$25,"") -> 49.154057 | I32: =IFERROR(H32*F32,"") -> 491.54057 | J32: =I32 -> 491.54057 | L32: =((J32-Costs_init!J32)/Costs_init!J32) -> 0
B33: 002 | D33: Design brand identity | E33: Junior software engineer | F33: 3 | G33: Hours | H33: =_xlfn.XLOOKUP(E33,$Q$20:$Q$25,$R$20:$R$25,"") -> 38.551814 | I33: =IFERROR(H33*F33,"") -> 115.65544 | J33: =I33 -> 115.65544 | L33: =((J33-Costs_init!J33)/Costs_init!J33) -> 0
B34: 003 | D34: Design project management | E34: Senior software engineer | F34: 8 | G34: Hours | H34: =_xlfn.XLOOKUP(E34,$Q$20:$Q$25,$R$20:$R$25,"") -> 43.846666 | I34: =IFERROR(H34*F34,"") -> 350.77333 | J34: =I34 -> 350.77333 | L34: =((J34-Costs_init!J34)/Costs_init!J34) -> 0
B35: 004 | D35: Design stakeholder management | E35: Senior software engineer | F35: 4 | G35: Hours | H35: =_xlfn.XLOOKUP(E35,$Q$20:$Q$25,$R$20:$R$25,"") -> 43.846666 | I35: =IFERROR(H35*F35,"") -> 175.38667 | J35: =I35 -> 175.38667 | L35: =((J35-Costs_init!J35)/Costs_init!J35) -> 0
B36: 005 | D36: Design requirement management | E36: Senior software engineer | F36: 6 | G36: Hours | H36: =_xlfn.XLOOKUP(E36,$Q$20:$Q$25,$R$20:$R$25,"") -> 43.846666 | I36: =IFERROR(H36*F36,"") -> 263.08 | J36: =I36 -> 263.08 | L36: =((J36-Costs_init!J36)/Costs_init!J36) -> 0
B37: 006 | D37: Design user management | E37: Senior software engineer | F37: 12 | G37: Hours | H37: =_xlfn.XLOOKUP(E37,$Q$20:$Q$25,$R$20:$R$25,"") -> 43.846666 | I37: =IFERROR(H37*F37,"") -> 526.16 | J37: =I37 -> 526.16 | L37: =((J37-Costs_init!J37)/Costs_init!J37) -> 0.2
B38: 007 | D38: Design document management | E38: Senior software engineer | F38: 10 | G38: Hours | H38: =_xlfn.XLOOKUP(E38,$Q$20:$Q$25,$R$20:$R$25,"") -> 43.846666 | I38: =IFERROR(H38*F38,"") -> 438.46666 | J38: =I38 -> 438.46666 | L38: =((J38-Costs_init!J38)/Costs_init!J38) -> 0
A39: 04 | D39: Set up SonarQube for Quality Assurance | E39: Senior software engineer | F39: 6 | G39: Hours | H39: =_xlfn.XLOOKUP(E39,$Q$20:$Q$25,$R$20:$R$25,"") -> 43.846666 | I39: =IFERROR(H39*F39,"") -> 263.08 | J39: =SUM(I39) -> 263.08 | K39: =SUM(J39) -> 263.08 | L39: =((K39-Costs_init!K39)/Costs_init!K39) -> 1
A40: 05 | D40: Development | H40: =_xlfn.XLOOKUP(E40,$Q$20:$Q$25,$R$20:$R$25,"") | I40: =IFERROR(H40*F40,"") | K40: =SUM(J41:J50) -> 4485.1818 | L40: =((K40-Costs_init!K40)/Costs_init!K40) -> 0.022403762
...
